<?xml version="1.0" encoding="UTF-8"?><testrun name="SortToolsTest (1)" project="Project 1" tests="3" started="3" failures="0" errors="1" ignored="0">
  <testsuite name="assignment1.SortToolsTest" time="0.004">
    <testcase name="testFindFoundFull" classname="assignment1.SortToolsTest" time="0.001"/>
    <testcase name="testIsSorted" classname="assignment1.SortToolsTest" time="0.0"/>
    <testcase name="testInsertGeneralPartialEnd" classname="assignment1.SortToolsTest" time="0.003">
      <error>java.lang.ArrayIndexOutOfBoundsException: 4&#13;
	at assignment1.SortTools.insertGeneral(SortTools.java:72)&#13;
	at assignment1.SortToolsTest.testInsertGeneralPartialEnd(SortToolsTest.java:39)&#13;
	at sun.reflect.NativeMethodAccessorImpl.invoke0(Native Method)&#13;
	at sun.reflect.NativeMethodAccessorImpl.invoke(Unknown Source)&#13;
	at sun.reflect.DelegatingMethodAccessorImpl.invoke(Unknown Source)&#13;
	at java.lang.reflect.Method.invoke(Unknown Source)&#13;
	at org.junit.runners.model.FrameworkMethod$1.runReflectiveCall(FrameworkMethod.java:50)&#13;
	at org.junit.internal.runners.model.ReflectiveCallable.run(ReflectiveCallable.java:12)&#13;
	at org.junit.runners.model.FrameworkMethod.invokeExplosively(FrameworkMethod.java:47)&#13;
	at org.junit.internal.runners.statements.InvokeMethod.evaluate(InvokeMethod.java:17)&#13;
	at org.junit.internal.runners.statements.FailOnTimeout$CallableStatement.call(FailOnTimeout.java:298)&#13;
	at org.junit.internal.runners.statements.FailOnTimeout$CallableStatement.call(FailOnTimeout.java:292)&#13;
	at java.util.concurrent.FutureTask.run(Unknown Source)&#13;
	at java.lang.Thread.run(Unknown Source)&#13;
&#13;
</error>
    </testcase>
  </testsuite>
</testrun>
